Workbook

Sheet Inventory
A1: 10X BAR STOCK MANAGEMENT
A3: Particular | B3: Category | C3: Opening Stock | D3: Stock IN | E3: Stock OUT | F3: Current Stock | G3: Reorder Level | H3: Remarks
A4: WELL WHISKEY | B4: WHISKEY | C4: 16 | D4: 0 | E4: 0 | F4: =C4+D4-E4 -> 16 | H4: =IF(F4<=G4,"REORDER","OK") -> OK
A5: JACK DANIELS | B5: WHISKEY | C5: 8 | D5: =SUMIF('Stock In'!$C:$C,A5,'Stock In'!$D:$D) -> 0 | E5: 0 | F5: =C5+D5-E5 -> 8 | H5: =IF(F5<=G5,"REORDER","OK") -> OK
A6: MAKERS MARK | B6: WHISKEY | C6: 6 | D6: =SUMIF('Stock In'!$C:$C,A6,'Stock In'!$D:$D) -> 0 | E6: 0 | F6: =C6+D6-E6 -> 6 | H6: =IF(F6<=G6,"REORDER","OK") -> OK
A7: WOODFORD RESERVE | B7: WHISKEY | C7: 4 | D7: =SUMIF('Stock In'!$C:$C,A7,'Stock In'!$D:$D) -> 0 | E7: 0 | F7: =C7+D7-E7 -> 4 | H7: =IF(F7<=G7,"REORDER","OK") -> OK
A8: BUFFALO TRACE | B8: WHISKEY | C8: 3 | D8: =SUMIF('Stock In'!$C:$C,A8,'Stock In'!$D:$D) -> 0 | E8: 0 | F8: =C8+D8-E8 -> 3 | H8: =IF(F8<=G8,"REORDER","OK") -> OK
A9: CROWN ROYAL | B9: WHISKEY | C9: 12 | D9: =SUMIF('Stock In'!$C:$C,A9,'Stock In'!$D:$D) -> 0 | E9: 0 | F9: =C9+D9-E9 -> 12 | H9: =IF(F9<=G9,"REORDER","OK") -> OK
A10: CROWN ROYAL APPLE | B10: WHISKEY | C10: 7 | D10: =SUMIF('Stock In'!$C:$C,A10,'Stock In'!$D:$D) -> 0 | E10: 1 | F10: =C10+D10-E10 -> 6 | H10: =IF(F10<=G10,"REORDER","OK") -> OK
A11: CROWN ROYAL VANILLA | B11: WHISKEY | C11: 5 | D11: =SUMIF('Stock In'!$C:$C,A11,'Stock In'!$D:$D) -> 0 | E11: 0 | F11: =C11+D11-E11 -> 5 | H11: =IF(F11<=G11,"REORDER","OK") -> OK
A12: CROWN ROYAL PEACH | B12: WHISKEY | C12: 3 | D12: =SUMIF('Stock In'!$C:$C,A12,'Stock In'!$D:$D) -> 0 | E12: 0 | F12: =C12+D12-E12 -> 3 | H12: =IF(F12<=G12,"REORDER","OK") -> OK
A13: JAMESON | B13: WHISKEY | C13: 8 | D13: =SUMIF('Stock In'!$C:$C,A13,'Stock In'!$D:$D) -> 0 | E13: 0 | F13: =C13+D13-E13 -> 8 | H13: =IF(F13<=G13,"REORDER","OK") -> OK
A14: JAMESON ORANGE | B14: WHISKEY | C14: 7 | D14: =SUMIF('Stock In'!$C:$C,A14,'Stock In'!$D:$D) -> 0 | E14: 0 | F14: =C14+D14-E14 -> 7 | H14: =IF(F14<=G14,"REORDER","OK") -> OK
A15: TX WHISKEY | B15: WHISKEY | C15: 5 | D15: =SUMIF('Stock In'!$C:$C,A15,'Stock In'!$D:$D) -> 0 | E15: 0 | F15: =C15+D15-E15 -> 5 | H15: =IF(F15<=G15,"REORDER","OK") -> OK
A16: BUCHANAN | B16: WHISKEY | C16: 7 | D16: =SUMIF('Stock In'!$C:$C,A16,'Stock In'!$D:$D) -> 0 | E16: 0 | F16: =C16+D16-E16 -> 7 | H16: =IF(F16<=G16,"REORDER","OK") -> OK
A17: BUCHANAN PINEAPPLE | B17: WHISKEY | C17: 6 | D17: =SUMIF('Stock In'!$C:$C,A17,'Stock In'!$D:$D) -> 0 | E17: 0 | F17: =C17+D17-E17 -> 6 | H17: =IF(F17<=G17,"REORDER","OK") -> OK
A18: McAllen 18 Yr | B18: WHISKEY | C18: 1 | D18: =SUMIF('Stock In'!$C:$C,A18,'Stock In'!$D:$D) -> 0 | E18: 0 | F18: =IF(A18="","",C18+D18-E18) -> 1 | H18: =IF(A18="","",IF(F18<=G18,"REORDER","OK")) -> OK
A19: McAllen 12 Yr | B19: WHISKEY | C19: 1 | D19: =SUMIF('Stock In'!$C:$C,A19,'Stock In'!$D:$D) -> 0 | E19: 0 | F19: 0 | H19: =IF(A19="","",IF(F19<=G19,"REORDER","OK")) -> REORDER
A20: BLUE LABEL | B20: WHISKEY | C20: 1 | D20: =SUMIF('Stock In'!$C:$C,A20,'Stock In'!$D:$D) -> 0 | E20: 0 | F20: =IF(A20="","",C20+D20-E20) -> 1 | H20: =IF(A20="","",IF(F20<=G20,"REORDER","OK")) -> OK
A21: RED LABEL | B21: WHISKEY | C21: 2 | D21: =SUMIF('Stock In'!$C:$C,A21,'Stock In'!$D:$D) -> 0 | E21: 0 | F21: =IF(A21="","",C21+D21-E21) -> 2 | H21: =IF(A21="","",IF(F21<=G21,"REORDER","OK")) -> OK
A22: BLACK LABEL | B22: WHISKEY | C22: 5 | D22: =SUMIF('Stock In'!$C:$C,A22,'Stock In'!$D:$D) -> 0 | E22: 0 | F22: =IF(A22="","",C22+D22-E22) -> 5 | H22: =IF(A22="","",IF(F22<=G22,"REORDER","OK")) -> OK
A23: DEWARS | B23: WHISKEY | C23: 1 | D23: =SUMIF('Stock In'!$C:$C,A23,'Stock In'!$D:$D) -> 0 | E23: 0 | F23: =IF(A23="","",C23+D23-E23) -> 1 | H23: =IF(A23="","",IF(F23<=G23,"REORDER","OK")) -> OK
A24: DEEP EDDY LEMON | B24: VODKA | C24: 3 | D24: =SUMIF('Stock In'!$C:$C,A24,'Stock In'!$D:$D) -> 0 | E24: 0 | F24: =IF(A24="","",C24+D24-E24) -> 3 | H24: =IF(A24="","",IF(F24<=G24,"REORDER","OK")) -> OK
A25: DEEP EDDY RUBY | B25: VODKA | C25: 5 | D25: =SUMIF('Stock In'!$C:$C,A25,'Stock In'!$D:$D) -> 0 | E25: =IF(A25="","",SUMIF('Stock Out'!$C:$C,A25,'Stock Out'!$D:$D)) -> 0 | F25: =IF(A25="","",C25+D25-E25) -> 5 | H25: =IF(A25="","",IF(F25<=G25,"REORDER","OK")) -> OK
A26: GREY GOOSE | B26: VODKA | C26: 7 | D26: =SUMIF('Stock In'!$C:$C,A26,'Stock In'!$D:$D) -> 0 | E26: 0 | F26: =IF(A26="","",C26+D26-E26) -> 7 | H26: =IF(A26="","",IF(F26<=G26,"REORDER","OK")) -> OK
A27: KETTLE ONE | B27: VODKA | C27: 2 | D27: =SUMIF('Stock In'!$C:$C,A27,'Stock In'!$D:$D) -> 0 | E27: 0 | F27: =IF(A27="","",C27+D27-E27) -> 2 | H27: =IF(A27="","",IF(F27<=G27,"REORDER","OK")) -> OK
A28: Titos | B28: VODKA | C28: 8 | D28: 0 | E28: 0 | F28: =IF(A28="","",C28+D28-E28) -> 8 | H28: =IF(A28="","",IF(F28<=G28,"REORDER","OK")) -> OK
A29: WELL VODKA | B29: VODKA | C29: 15 | D29: 0 | E29: 0 | F29: =IF(A29="","",C29+D29-E29) -> 15 | H29: =IF(A29="","",IF(F29<=G29,"REORDER","OK")) -> OK
A30: WESTERNSON STRAWBERRY | B30: VODKA | C30: 6 | D30: 0 | E30: 0 | F30: =IF(A30="","",C30+D30-E30) -> 6 | H30: =IF(A30="","",IF(F30<=G30,"REORDER","OK")) -> OK
A31: CASAMIGOS BLANCO | B31: TEQUILA | C31: 9 | D31: 0 | E31: 0 | F31: =IF(A31="","",C31+D31-E31) -> 9 | H31: =IF(A31="","",IF(F31<=G31,"REORDER","OK")) -> OK
A32: CASAMIGOS REPO | B32: TEQUILA | C32: 8 | D32: 0 | E32: 0 | F32: =IF(A32="","",C32+D32-E32) -> 8 | H32: =IF(A32="","",IF(F32<=G32,"REORDER","OK")) -> OK
A33: CLASE AZUL | B33: TEQUILA | C33: 2 | D33: 0 | E33: 0 | F33: =IF(A33="","",C33+D33-E33) -> 2 | H33: =IF(A33="","",IF(F33<=G33,"REORDER","OK")) -> OK
A34: DON JULIO 1942 | B34: TEQUILA | C34: 1 | D34: 0 | E34: 0 | F34: =IF(A34="","",C34+D34-E34) -> 1 | H34: =IF(A34="","",IF(F34<=G34,"REORDER","OK")) -> OK
A35: DON JULIO 70 | B35: TEQUILA | C35: 1 | D35: 0 | E35: 0 | F35: 3 | H35: =IF(A35="","",IF(F35<=G35,"REORDER","OK")) -> OK
A36: DON JULIO ANEJO | B36: TEQUILA | C36: 6 | D36: 0 | E36: 0 | F36: =IF(A36="","",C36+D36-E36) -> 6 | H36: =IF(A36="","",IF(F36<=G36,"REORDER","OK")) -> OK
A37: DON JULIO BLANCO | B37: TEQUILA | C37: 2 | D37: 0 | E37: 0 | F37: =IF(A37="","",C37+D37-E37) -> 2 | H37: =IF(A37="","",IF(F37<=G37,"REORDER","OK")) -> OK
A38: DON JULIO REPO | B38: TEQUILA | C38: 5 | D38: 0 | E38: 1 | F38: =IF(A38="","",C38+D38-E38) -> 4 | H38: =IF(A38="","",IF(F38<=G38,"REORDER","OK")) -> OK
A39: ESPOLON | B39: TEQUILA | C39: 7 | D39: 0 | E39: 0 | F39: =IF(A39="","",C39+D39-E39) -> 7 | H39: =IF(A39="","",IF(F39<=G39,"REORDER","OK")) -> OK
A40: ESPOLON REPO | B40: TEQUILA | C40: 4 | D40: 0 | E40: 0 | F40: =IF(A40="","",C40+D40-E40) -> 4 | H40: =IF(A40="","",IF(F40<=G40,"REORDER","OK")) -> OK
A41: PATRON SLIVER | B41: TEQUILA | C41: 3 | D41: 0 | E41: 0 | F41: =IF(A41="","",C41+D41-E41) -> 3 | H41: =IF(A41="","",IF(F41<=G41,"REORDER","OK")) -> OK
...

Sheet Dashboard
A1: 10X BAR INVENTORY DASHBOARD
A3: Summary | B3: Value | E3: HOW TO USE 1. Enter opening stock in Inventory. 2. Record every purchase in Stock In. 3. Record every sale/use in Stock Out. 4. Current stock and reorder status update automatically.
A4: Total Product Lines | B4: =COUNTIF(Inventory!A4:A150,"<>") -> 119
A5: Total Bottles in Stock | B5: =SUM(Inventory!F4:F150) -> 1050
A6: Items to Reorder | B6: =COUNTIF(Inventory!H4:H150,"REORDER") -> 13
A9: Low Stock Item | B9: Current Stock | C9: Reorder Level
A10: {=_xlfn._xlws.FILTER(Inventory!A4:A150,Inventory!H4:H150="REORDER","No low stock items")} -> McAllen 12 Yr | B10: {=_xlfn._xlws.FILTER(Inventory!F4:F150,Inventory!H4:H150="REORDER","")} -> 0 | C10: {=_xlfn._xlws.FILTER(Inventory!G4:G150,Inventory!H4:H150="REORDER","")} -> 0
A11: WELL RUM COCONUT | B11: 0 | C11: 0
A12: Bud light | B12: 0 | C12: 0
A13: Coors | B13: 0 | C13: 0
A14: High noon | B14: 0 | C14: 0
A15: Miller | B15: 0 | C15: 0
A16: Nutrl | B16: 0 | C16: 0
A17: Twisted Tea | B17: 0 | C17: 0
A18: Ultra 00 | B18: 0 | C18: 0
A19: White Claw | B19: 0 | C19: 0
A20: SWEET N SOUR | B20: 0 | C20: 0
A21: Pineapple Juice | B21: 0 | C21: 0
A22: Cranberry Juice | B22: 0 | C22: 0

Sheet Stock In
A1: STOCK IN / PURCHASE ENTRY
A3: Date | B3: Invoice # | C3: Item | D3: Quantity | E3: Supplier | F3: Entered By

Sheet Stock Out
A1: STOCK OUT / USAGE ENTRY
A3: Date | B3: Reference # | C3: Item | D3: Quantity | E3: Reason | F3: Entered By

Sheet Patio Bar
A1: 10X FRONT BAR STOCK
A3: Particular | B3: Category | C3: Opening Stock | D3: Opening Date | E3: Stock IN | F3: Stock OUT | G3: Current Stock | H3: Reorder Level | I3: Remarks
A4: CALYPSO SILVER | B4: RUM | C4: 1.87 | D4: 46246 | E4: 0 | F4: 0 | G4: 1.87 | H4: 1 | I4: OK
A5: PEACH SHNAPPS | B5: OTHER | C5: 1.67 | D5: 46246 | E5: 0 | F5: 0 | G5: 1.67 | H5: 1 | I5: OK
A6: Boston butter scotch | B6: OTHER | C6: 1 | D6: 46246 | E6: 0 | F6: 0 | G6: 1 | H6: 1 | I6: REORDER
A7: TAAKA | B7: VODKA | C7: 2.95 | D7: 46246 | E7: 0 | F7: 0 | G7: 2.95 | H7: 1 | I7: OK
A8: del viejo silver tequilla | B8: TEQUILA | C8: 3 | D8: 46246 | E8: 0 | F8: 0 | G8: 3 | H8: 1 | I8: OK
A9: CASAMIGOS | B9: TEQUILA | C9: 2.8 | D9: 46246 | E9: 0 | F9: 0 | G9: 2.8 | H9: 1 | I9: OK
A10: TRIPLE SEC | B10: OTHER | C10: 1.75 | D10: 46246 | E10: 0 | F10: 0 | G10: 1.75 | H10: 1 | I10: OK
A11: WATERMELON SHNAPPS | B11: OTHER | C11: 1.3 | D11: 46246 | E11: 0 | F11: 0 | G11: 1.3 | H11: 1 | I11: OK
A12: DEEP EDDY LEMON | B12: VODKA | C12: 1 | D12: 46246 | E12: 0 | F12: 0 | G12: 1 | H12: 1 | I12: REORDER
A13: BARTON NATURALS | B13: VODKA | C13: 2 | D13: 46246 | E13: 0 | F13: 0 | G13: 2 | H13: 1 | I13: OK
A14: KENTUCKY GENTLEMAN | B14: WHISKEY | C14: 1.67 | D14: 46246 | E14: 0 | F14: 0 | G14: 1.67 | H14: 1 | I14: OK
A15: BARTON'S LONG ISLAND | B15: OTHER | C15: 0.67 | D15: 46246 | E15: 0 | F15: 0 | G15: 0.67 | H15: 1 | I15: REORDER
... A45: MALIBU | B45: RUM | C45: 0.25 | D45: 46246 | E45: 0 | F45: 0 | G45: 0.25 | H45: 1 | I45: REORDER

Sheet Back Bar
A1: 10X BACK BAR STOCK
A3: Particular | B3: Category | C3: Opening Stock | D3: Opening Date | E3: Stock IN | F3: Stock OUT | G3: Current Stock | H3: Reorder Level
A4: CALYPSO SILVER | B4: RUM | C4: 2.25 | D4: 46246 | E4: 0 | F4: 0 | G4: 2.25 | H4: 1
A5: KENTUCKY GENTLEMAN | B5: WHISKEY | C5: 2.75 | D5: 46246 | E5: 0 | F5: 0 | G5: 2.75 | H5: 1
A6: WATERMELON SHNAPPS | B6: OTHER | C6: 0.2 | D6: 46246 | E6: 0 | F6: 0 | G6: 0.2 | H6: 1
A7: PEACH SHNAPPS | B7: OTHER | C7: 1.75 | D7: 46246 | E7: 0 | F7: 0 | G7: 1.75 | H7: 1
A8: TRIPLE SEC | B8: OTHER | C8: 0.33 | D8: 46246 | E8: 0 | F8: 0 | G8: 0.33 | H8: 1
A9: DEWARS | B9: WHISKEY | C9: 1 | D9: 46246 | E9: 0 | F9: 0 | G9: 1 | H9: 1
A10: SCREWBALL | B10: OTHER | C10: 0.67 | D10: 46246 | E10: 0 | F10: 0 | G10: 0.67 | H10: 1
A11: CROWN ROYAL VANILLA | B11: WHISKEY | C11: 0.5 | D11: 46246 | E11: 0 | F11: 0 | G11: 0.5 | H11: 1
A12: CROWN ROYAL PEACH | B12: WHISKEY | C12: 1.8 | D12: 46246 | E12: 0 | F12: 0 | G12: 1.8 | H12: 1
A13: JAMESON ORANGE | B13: WHISKEY | C13: 0.25 | D13: 46246 | E13: 0 | F13: 0 | G13: 0.25 | H13: 1
A14: CAPTAIN MORGAN SPICED | B14: RUM | C14: 0.67 | D14: 46246 | E14: 0 | F14: 0 | G14: 0.67 | H14: 1
A15: WOODFORD RESERVE | B15: WHISKEY | C15: 1 | D15: 46246 | E15: 0 | F15: 0 | G15: 1 | H15: 1
... A47: MALIBU | B47: RUM | C47: 0.25 | D47: 46246 | E47: 0 | F47: 0 | G47: 0.25 | H47: 1

Sheet Lists
A1: Item | B1: Category
A2: WELL WHISKEY | B2: WHISKEY
A3: JACK DANIELS | B3: WHISKEY
A4: MAKERS MARK | B4: WHISKEY
A5: WOODFORD RESERVE | B5: WHISKEY
A6: BUFFALO TRACE | B6: WHISKEY
A7: CROWN ROYAL | B7: WHISKEY
A8: CROWN ROYAL APPLE | B8: WHISKEY
A9: CROWN ROYAL VANILLA | B9: WHISKEY
A10: CROWN ROYAL PEACH | B10: WHISKEY
A11: JAMESON | B11: WHISKEY
A12: JAMESON ORANGE | B12: WHISKEY
... A14: BUCANA | B14: WHISKEY
